2025-05-26 20:45:12,066 INFO    MainThread:16403 [wandb_init.py:setup_run_log_directory():724] Logging user logs to /home/hugo/TFG/Notebooks/wandb/run-20250526_204512-2agwerno/logs/debug.log
2025-05-26 20:45:12,066 INFO    MainThread:16403 [wandb_init.py:setup_run_log_directory():725] Logging internal logs to /home/hugo/TFG/Notebooks/wandb/run-20250526_204512-2agwerno/logs/debug-internal.log
2025-05-26 20:45:12,067 INFO    MainThread:16403 [wandb_init.py:monkeypatch_ipython():643] configuring jupyter hooks <wandb.sdk.wandb_init._WandbInit object at 0x7bed347e0830>
2025-05-26 20:45:12,067 INFO    MainThread:16403 [wandb_init.py:init():852] calling init triggers
2025-05-26 20:45:12,067 INFO    MainThread:16403 [wandb_init.py:init():857] wandb.init called with sweep_config: {}
config: {'batch_size': 32, 'learning_rate': 1e-05, 'hidden_size': 128, 'epochs': 50, 'fold': 1, '_wandb': {}}
2025-05-26 20:45:12,067 INFO    MainThread:16403 [wandb_init.py:init():893] starting backend
2025-05-26 20:45:12,067 INFO    MainThread:16403 [wandb_init.py:init():897] sending inform_init request
2025-05-26 20:45:12,068 INFO    MainThread:16403 [backend.py:_multiprocessing_setup():101] multiprocessing start_methods=fork,spawn,forkserver, using: spawn
2025-05-26 20:45:12,068 INFO    MainThread:16403 [wandb_init.py:init():907] backend started and connected
2025-05-26 20:45:12,070 INFO    MainThread:16403 [wandb_run.py:_label_probe_notebook():1369] probe notebook
2025-05-26 20:45:12,071 INFO    MainThread:16403 [wandb_init.py:init():1002] updated telemetry
2025-05-26 20:45:12,075 INFO    MainThread:16403 [wandb_init.py:init():1026] communicating run to backend with 90.0 second timeout
2025-05-26 20:45:12,741 INFO    MainThread:16403 [wandb_init.py:init():1101] starting run threads in backend
2025-05-26 20:45:12,882 INFO    MainThread:16403 [wandb_run.py:_console_start():2566] atexit reg
2025-05-26 20:45:12,882 INFO    MainThread:16403 [wandb_run.py:_redirect():2414] redirect: wrap_raw
2025-05-26 20:45:12,882 INFO    MainThread:16403 [wandb_run.py:_redirect():2483] Wrapping output streams.
2025-05-26 20:45:12,882 INFO    MainThread:16403 [wandb_run.py:_redirect():2506] Redirects installed.
2025-05-26 20:45:12,883 INFO    MainThread:16403 [wandb_init.py:init():1147] run started, returning control to user process
2025-05-26 20:45:13,955 WARNING MsgRouterThr:16403 [router.py:message_loop():63] [no run ID] message_loop has been closed
Traceback (most recent call last):
  File "/home/hugo/anaconda3/lib/python3.12/site-packages/wandb/sdk/interface/router_sock.py", line 27, in _read_message
    return self._sock_client.read_server_response(timeout=1)
           ^^^^^^^^^^^^^^^^^^^^^^^^^^^^^^^^^^^^^^^^^^^^^^^^^
  File "/home/hugo/anaconda3/lib/python3.12/site-packages/wandb/sdk/lib/sock_client.py", line 235, in read_server_response
    data = self._read_packet_bytes(timeout=timeout)
           ^^^^^^^^^^^^^^^^^^^^^^^^^^^^^^^^^^^^^^^^
  File "/home/hugo/anaconda3/lib/python3.12/site-packages/wandb/sdk/lib/sock_client.py", line 220, in _read_packet_bytes
    raise SockClientClosedError
wandb.sdk.lib.sock_client.SockClientClosedError

The above exception was the direct cause of the following exception:

Traceback (most recent call last):
  File "/home/hugo/anaconda3/lib/python3.12/site-packages/wandb/sdk/interface/router.py", line 56, in message_loop
    msg = self._read_message()
          ^^^^^^^^^^^^^^^^^^^^
  File "/home/hugo/anaconda3/lib/python3.12/site-packages/wandb/sdk/interface/router_sock.py", line 29, in _read_message
    raise MessageRouterClosedError from e
wandb.sdk.interface.router.MessageRouterClosedError
2025-05-26 20:45:13,956 INFO    MsgRouterThr:16403 [mailbox.py:close():129] [no run ID] Closing mailbox, abandoning 7 handles.
2025-05-26 20:45:18,313 INFO    MainThread:16403 [wandb_init.py:_post_run_cell_hook():613] [no run ID] resuming backend
2025-05-26 20:48:07,142 INFO    MainThread:16403 [jupyter.py:save_ipynb():401] [no run ID] not saving jupyter notebook
2025-05-26 20:48:07,142 INFO    MainThread:16403 [wandb_init.py:_pre_run_cell_hook():602] [no run ID] pausing backend
2025-05-26 20:48:07,142 ERROR   MainThread:16403 [redirect.py:_on_write():664] [no run ID] error in stdout callback
Traceback (most recent call last):
  File "/home/hugo/anaconda3/lib/python3.12/site-packages/IPython/core/events.py", line 82, in trigger
    func(*args, **kwargs)
  File "/home/hugo/anaconda3/lib/python3.12/site-packages/wandb/sdk/wandb_init.py", line 603, in _pre_run_cell_hook
    self.backend.interface.publish_pause()
  File "/home/hugo/anaconda3/lib/python3.12/site-packages/wandb/sdk/interface/interface.py", line 771, in publish_pause
    self._publish_pause(pause)
  File "/home/hugo/anaconda3/lib/python3.12/site-packages/wandb/sdk/interface/interface_shared.py", line 289, in _publish_pause
    self._publish(rec)
  File "/home/hugo/anaconda3/lib/python3.12/site-packages/wandb/sdk/interface/interface_sock.py", line 39, in _publish
    self._sock_client.send_record_publish(record)
  File "/home/hugo/anaconda3/lib/python3.12/site-packages/wandb/sdk/lib/sock_client.py", line 174, in send_record_publish
    self.send_server_request(server_req)
  File "/home/hugo/anaconda3/lib/python3.12/site-packages/wandb/sdk/lib/sock_client.py", line 154, in send_server_request
    self._send_message(msg)
  File "/home/hugo/anaconda3/lib/python3.12/site-packages/wandb/sdk/lib/sock_client.py", line 151, in _send_message
    self._sendall_with_error_handle(header + data)
  File "/home/hugo/anaconda3/lib/python3.12/site-packages/wandb/sdk/lib/sock_client.py", line 130, in _sendall_with_error_handle
    sent = self._sock.send(data)
           ^^^^^^^^^^^^^^^^^^^^^
BrokenPipeError: [Errno 32] Broken pipe

During handling of the above exception, another exception occurred:

Traceback (most recent call last):
  File "/home/hugo/anaconda3/lib/python3.12/site-packages/wandb/sdk/lib/redirect.py", line 662, in _on_write
    cb(written_data)
  File "/home/hugo/anaconda3/lib/python3.12/site-packages/wandb/sdk/wandb_run.py", line 2487, in <lambda>
    lambda data: self._console_raw_callback("stdout", data),
                 ^^^^^^^^^^^^^^^^^^^^^^^^^^^^^^^^^^^^^^^^^^
  File "/home/hugo/anaconda3/lib/python3.12/site-packages/wandb/sdk/wandb_run.py", line 406, in wrapper
    return func(self, *args, **kwargs)
           ^^^^^^^^^^^^^^^^^^^^^^^^^^^
  File "/home/hugo/anaconda3/lib/python3.12/site-packages/wandb/sdk/wandb_run.py", line 464, in wrapper_fn
    return func(self, *args, **kwargs)
           ^^^^^^^^^^^^^^^^^^^^^^^^^^^
  File "/home/hugo/anaconda3/lib/python3.12/site-packages/wandb/sdk/wandb_run.py", line 1632, in _console_raw_callback
    self._backend.interface.publish_output_raw(name, data)
  File "/home/hugo/anaconda3/lib/python3.12/site-packages/wandb/sdk/interface/interface.py", line 763, in publish_output_raw
    self._publish_output_raw(o)
  File "/home/hugo/anaconda3/lib/python3.12/site-packages/wandb/sdk/interface/interface_shared.py", line 38, in _publish_output_raw
    self._publish(rec)
  File "/home/hugo/anaconda3/lib/python3.12/site-packages/wandb/sdk/interface/interface_sock.py", line 39, in _publish
    self._sock_client.send_record_publish(record)
  File "/home/hugo/anaconda3/lib/python3.12/site-packages/wandb/sdk/lib/sock_client.py", line 174, in send_record_publish
    self.send_server_request(server_req)
  File "/home/hugo/anaconda3/lib/python3.12/site-packages/wandb/sdk/lib/sock_client.py", line 154, in send_server_request
    self._send_message(msg)
  File "/home/hugo/anaconda3/lib/python3.12/site-packages/wandb/sdk/lib/sock_client.py", line 151, in _send_message
    self._sendall_with_error_handle(header + data)
  File "/home/hugo/anaconda3/lib/python3.12/site-packages/wandb/sdk/lib/sock_client.py", line 130, in _sendall_with_error_handle
    sent = self._sock.send(data)
           ^^^^^^^^^^^^^^^^^^^^^
BrokenPipeError: [Errno 32] Broken pipe
2025-05-26 20:48:07,145 ERROR   MainThread:16403 [redirect.py:_on_write():664] [no run ID] error in stdout callback
Traceback (most recent call last):
  File "/home/hugo/anaconda3/lib/python3.12/site-packages/IPython/core/events.py", line 82, in trigger
    func(*args, **kwargs)
  File "/home/hugo/anaconda3/lib/python3.12/site-packages/wandb/sdk/wandb_init.py", line 603, in _pre_run_cell_hook
    self.backend.interface.publish_pause()
  File "/home/hugo/anaconda3/lib/python3.12/site-packages/wandb/sdk/interface/interface.py", line 771, in publish_pause
    self._publish_pause(pause)
  File "/home/hugo/anaconda3/lib/python3.12/site-packages/wandb/sdk/interface/interface_shared.py", line 289, in _publish_pause
    self._publish(rec)
  File "/home/hugo/anaconda3/lib/python3.12/site-packages/wandb/sdk/interface/interface_sock.py", line 39, in _publish
    self._sock_client.send_record_publish(record)
  File "/home/hugo/anaconda3/lib/python3.12/site-packages/wandb/sdk/lib/sock_client.py", line 174, in send_record_publish
    self.send_server_request(server_req)
  File "/home/hugo/anaconda3/lib/python3.12/site-packages/wandb/sdk/lib/sock_client.py", line 154, in send_server_request
    self._send_message(msg)
  File "/home/hugo/anaconda3/lib/python3.12/site-packages/wandb/sdk/lib/sock_client.py", line 151, in _send_message
    self._sendall_with_error_handle(header + data)
  File "/home/hugo/anaconda3/lib/python3.12/site-packages/wandb/sdk/lib/sock_client.py", line 130, in _sendall_with_error_handle
    sent = self._sock.send(data)
           ^^^^^^^^^^^^^^^^^^^^^
BrokenPipeError: [Errno 32] Broken pipe

During handling of the above exception, another exception occurred:

Traceback (most recent call last):
  File "/home/hugo/anaconda3/lib/python3.12/site-packages/wandb/sdk/lib/redirect.py", line 662, in _on_write
    cb(written_data)
  File "/home/hugo/anaconda3/lib/python3.12/site-packages/wandb/sdk/wandb_run.py", line 2487, in <lambda>
    lambda data: self._console_raw_callback("stdout", data),
                 ^^^^^^^^^^^^^^^^^^^^^^^^^^^^^^^^^^^^^^^^^^
  File "/home/hugo/anaconda3/lib/python3.12/site-packages/wandb/sdk/wandb_run.py", line 406, in wrapper
    return func(self, *args, **kwargs)
           ^^^^^^^^^^^^^^^^^^^^^^^^^^^
  File "/home/hugo/anaconda3/lib/python3.12/site-packages/wandb/sdk/wandb_run.py", line 464, in wrapper_fn
    return func(self, *args, **kwargs)
           ^^^^^^^^^^^^^^^^^^^^^^^^^^^
  File "/home/hugo/anaconda3/lib/python3.12/site-packages/wandb/sdk/wandb_run.py", line 1632, in _console_raw_callback
    self._backend.interface.publish_output_raw(name, data)
  File "/home/hugo/anaconda3/lib/python3.12/site-packages/wandb/sdk/interface/interface.py", line 763, in publish_output_raw
    self._publish_output_raw(o)
  File "/home/hugo/anaconda3/lib/python3.12/site-packages/wandb/sdk/interface/interface_shared.py", line 38, in _publish_output_raw
    self._publish(rec)
  File "/home/hugo/anaconda3/lib/python3.12/site-packages/wandb/sdk/interface/interface_sock.py", line 39, in _publish
    self._sock_client.send_record_publish(record)
  File "/home/hugo/anaconda3/lib/python3.12/site-packages/wandb/sdk/lib/sock_client.py", line 174, in send_record_publish
    self.send_server_request(server_req)
  File "/home/hugo/anaconda3/lib/python3.12/site-packages/wandb/sdk/lib/sock_client.py", line 154, in send_server_request
    self._send_message(msg)
  File "/home/hugo/anaconda3/lib/python3.12/site-packages/wandb/sdk/lib/sock_client.py", line 151, in _send_message
    self._sendall_with_error_handle(header + data)
  File "/home/hugo/anaconda3/lib/python3.12/site-packages/wandb/sdk/lib/sock_client.py", line 130, in _sendall_with_error_handle
    sent = self._sock.send(data)
           ^^^^^^^^^^^^^^^^^^^^^
BrokenPipeError: [Errno 32] Broken pipe
2025-05-26 20:48:07,373 INFO    MainThread:16403 [wandb_init.py:_post_run_cell_hook():613] [no run ID] resuming backend
2025-05-26 20:48:07,373 ERROR   MainThread:16403 [redirect.py:_on_write():664] [no run ID] error in stdout callback
Traceback (most recent call last):
  File "/home/hugo/anaconda3/lib/python3.12/site-packages/IPython/core/events.py", line 82, in trigger
    func(*args, **kwargs)
  File "/home/hugo/anaconda3/lib/python3.12/site-packages/wandb/sdk/wandb_init.py", line 614, in _post_run_cell_hook
    self.backend.interface.publish_resume()
  File "/home/hugo/anaconda3/lib/python3.12/site-packages/wandb/sdk/interface/interface.py", line 779, in publish_resume
    self._publish_resume(resume)
  File "/home/hugo/anaconda3/lib/python3.12/site-packages/wandb/sdk/interface/interface_shared.py", line 293, in _publish_resume
    self._publish(rec)
  File "/home/hugo/anaconda3/lib/python3.12/site-packages/wandb/sdk/interface/interface_sock.py", line 39, in _publish
    self._sock_client.send_record_publish(record)
  File "/home/hugo/anaconda3/lib/python3.12/site-packages/wandb/sdk/lib/sock_client.py", line 174, in send_record_publish
    self.send_server_request(server_req)
  File "/home/hugo/anaconda3/lib/python3.12/site-packages/wandb/sdk/lib/sock_client.py", line 154, in send_server_request
    self._send_message(msg)
  File "/home/hugo/anaconda3/lib/python3.12/site-packages/wandb/sdk/lib/sock_client.py", line 151, in _send_message
    self._sendall_with_error_handle(header + data)
  File "/home/hugo/anaconda3/lib/python3.12/site-packages/wandb/sdk/lib/sock_client.py", line 130, in _sendall_with_error_handle
    sent = self._sock.send(data)
           ^^^^^^^^^^^^^^^^^^^^^
BrokenPipeError: [Errno 32] Broken pipe

During handling of the above exception, another exception occurred:

Traceback (most recent call last):
  File "/home/hugo/anaconda3/lib/python3.12/site-packages/wandb/sdk/lib/redirect.py", line 662, in _on_write
    cb(written_data)
  File "/home/hugo/anaconda3/lib/python3.12/site-packages/wandb/sdk/wandb_run.py", line 2487, in <lambda>
    lambda data: self._console_raw_callback("stdout", data),
                 ^^^^^^^^^^^^^^^^^^^^^^^^^^^^^^^^^^^^^^^^^^
  File "/home/hugo/anaconda3/lib/python3.12/site-packages/wandb/sdk/wandb_run.py", line 406, in wrapper
    return func(self, *args, **kwargs)
           ^^^^^^^^^^^^^^^^^^^^^^^^^^^
  File "/home/hugo/anaconda3/lib/python3.12/site-packages/wandb/sdk/wandb_run.py", line 464, in wrapper_fn
    return func(self, *args, **kwargs)
           ^^^^^^^^^^^^^^^^^^^^^^^^^^^
  File "/home/hugo/anaconda3/lib/python3.12/site-packages/wandb/sdk/wandb_run.py", line 1632, in _console_raw_callback
    self._backend.interface.publish_output_raw(name, data)
  File "/home/hugo/anaconda3/lib/python3.12/site-packages/wandb/sdk/interface/interface.py", line 763, in publish_output_raw
    self._publish_output_raw(o)
  File "/home/hugo/anaconda3/lib/python3.12/site-packages/wandb/sdk/interface/interface_shared.py", line 38, in _publish_output_raw
    self._publish(rec)
  File "/home/hugo/anaconda3/lib/python3.12/site-packages/wandb/sdk/interface/interface_sock.py", line 39, in _publish
    self._sock_client.send_record_publish(record)
  File "/home/hugo/anaconda3/lib/python3.12/site-packages/wandb/sdk/lib/sock_client.py", line 174, in send_record_publish
    self.send_server_request(server_req)
  File "/home/hugo/anaconda3/lib/python3.12/site-packages/wandb/sdk/lib/sock_client.py", line 154, in send_server_request
    self._send_message(msg)
  File "/home/hugo/anaconda3/lib/python3.12/site-packages/wandb/sdk/lib/sock_client.py", line 151, in _send_message
    self._sendall_with_error_handle(header + data)
  File "/home/hugo/anaconda3/lib/python3.12/site-packages/wandb/sdk/lib/sock_client.py", line 130, in _sendall_with_error_handle
    sent = self._sock.send(data)
           ^^^^^^^^^^^^^^^^^^^^^
BrokenPipeError: [Errno 32] Broken pipe
2025-05-26 20:48:07,374 ERROR   MainThread:16403 [redirect.py:_on_write():664] [no run ID] error in stdout callback
Traceback (most recent call last):
  File "/home/hugo/anaconda3/lib/python3.12/site-packages/IPython/core/events.py", line 82, in trigger
    func(*args, **kwargs)
  File "/home/hugo/anaconda3/lib/python3.12/site-packages/wandb/sdk/wandb_init.py", line 614, in _post_run_cell_hook
    self.backend.interface.publish_resume()
  File "/home/hugo/anaconda3/lib/python3.12/site-packages/wandb/sdk/interface/interface.py", line 779, in publish_resume
    self._publish_resume(resume)
  File "/home/hugo/anaconda3/lib/python3.12/site-packages/wandb/sdk/interface/interface_shared.py", line 293, in _publish_resume
    self._publish(rec)
  File "/home/hugo/anaconda3/lib/python3.12/site-packages/wandb/sdk/interface/interface_sock.py", line 39, in _publish
    self._sock_client.send_record_publish(record)
  File "/home/hugo/anaconda3/lib/python3.12/site-packages/wandb/sdk/lib/sock_client.py", line 174, in send_record_publish
    self.send_server_request(server_req)
  File "/home/hugo/anaconda3/lib/python3.12/site-packages/wandb/sdk/lib/sock_client.py", line 154, in send_server_request
    self._send_message(msg)
  File "/home/hugo/anaconda3/lib/python3.12/site-packages/wandb/sdk/lib/sock_client.py", line 151, in _send_message
    self._sendall_with_error_handle(header + data)
  File "/home/hugo/anaconda3/lib/python3.12/site-packages/wandb/sdk/lib/sock_client.py", line 130, in _sendall_with_error_handle
    sent = self._sock.send(data)
           ^^^^^^^^^^^^^^^^^^^^^
BrokenPipeError: [Errno 32] Broken pipe

During handling of the above exception, another exception occurred:

Traceback (most recent call last):
  File "/home/hugo/anaconda3/lib/python3.12/site-packages/wandb/sdk/lib/redirect.py", line 662, in _on_write
    cb(written_data)
  File "/home/hugo/anaconda3/lib/python3.12/site-packages/wandb/sdk/wandb_run.py", line 2487, in <lambda>
    lambda data: self._console_raw_callback("stdout", data),
                 ^^^^^^^^^^^^^^^^^^^^^^^^^^^^^^^^^^^^^^^^^^
  File "/home/hugo/anaconda3/lib/python3.12/site-packages/wandb/sdk/wandb_run.py", line 406, in wrapper
    return func(self, *args, **kwargs)
           ^^^^^^^^^^^^^^^^^^^^^^^^^^^
  File "/home/hugo/anaconda3/lib/python3.12/site-packages/wandb/sdk/wandb_run.py", line 464, in wrapper_fn
    return func(self, *args, **kwargs)
           ^^^^^^^^^^^^^^^^^^^^^^^^^^^
  File "/home/hugo/anaconda3/lib/python3.12/site-packages/wandb/sdk/wandb_run.py", line 1632, in _console_raw_callback
    self._backend.interface.publish_output_raw(name, data)
  File "/home/hugo/anaconda3/lib/python3.12/site-packages/wandb/sdk/interface/interface.py", line 763, in publish_output_raw
    self._publish_output_raw(o)
  File "/home/hugo/anaconda3/lib/python3.12/site-packages/wandb/sdk/interface/interface_shared.py", line 38, in _publish_output_raw
    self._publish(rec)
  File "/home/hugo/anaconda3/lib/python3.12/site-packages/wandb/sdk/interface/interface_sock.py", line 39, in _publish
    self._sock_client.send_record_publish(record)
  File "/home/hugo/anaconda3/lib/python3.12/site-packages/wandb/sdk/lib/sock_client.py", line 174, in send_record_publish
    self.send_server_request(server_req)
  File "/home/hugo/anaconda3/lib/python3.12/site-packages/wandb/sdk/lib/sock_client.py", line 154, in send_server_request
    self._send_message(msg)
  File "/home/hugo/anaconda3/lib/python3.12/site-packages/wandb/sdk/lib/sock_client.py", line 151, in _send_message
    self._sendall_with_error_handle(header + data)
  File "/home/hugo/anaconda3/lib/python3.12/site-packages/wandb/sdk/lib/sock_client.py", line 130, in _sendall_with_error_handle
    sent = self._sock.send(data)
           ^^^^^^^^^^^^^^^^^^^^^
BrokenPipeError: [Errno 32] Broken pipe
2025-05-26 20:48:07,416 INFO    MainThread:16403 [jupyter.py:save_ipynb():401] [no run ID] not saving jupyter notebook
2025-05-26 20:48:07,416 INFO    MainThread:16403 [wandb_init.py:_pre_run_cell_hook():602] [no run ID] pausing backend
2025-05-26 20:48:07,417 ERROR   MainThread:16403 [redirect.py:_on_write():664] [no run ID] error in stdout callback
Traceback (most recent call last):
  File "/home/hugo/anaconda3/lib/python3.12/site-packages/IPython/core/events.py", line 82, in trigger
    func(*args, **kwargs)
  File "/home/hugo/anaconda3/lib/python3.12/site-packages/wandb/sdk/wandb_init.py", line 603, in _pre_run_cell_hook
    self.backend.interface.publish_pause()
  File "/home/hugo/anaconda3/lib/python3.12/site-packages/wandb/sdk/interface/interface.py", line 771, in publish_pause
    self._publish_pause(pause)
  File "/home/hugo/anaconda3/lib/python3.12/site-packages/wandb/sdk/interface/interface_shared.py", line 289, in _publish_pause
    self._publish(rec)
  File "/home/hugo/anaconda3/lib/python3.12/site-packages/wandb/sdk/interface/interface_sock.py", line 39, in _publish
    self._sock_client.send_record_publish(record)
  File "/home/hugo/anaconda3/lib/python3.12/site-packages/wandb/sdk/lib/sock_client.py", line 174, in send_record_publish
    self.send_server_request(server_req)
  File "/home/hugo/anaconda3/lib/python3.12/site-packages/wandb/sdk/lib/sock_client.py", line 154, in send_server_request
    self._send_message(msg)
  File "/home/hugo/anaconda3/lib/python3.12/site-packages/wandb/sdk/lib/sock_client.py", line 151, in _send_message
    self._sendall_with_error_handle(header + data)
  File "/home/hugo/anaconda3/lib/python3.12/site-packages/wandb/sdk/lib/sock_client.py", line 130, in _sendall_with_error_handle
    sent = self._sock.send(data)
           ^^^^^^^^^^^^^^^^^^^^^
BrokenPipeError: [Errno 32] Broken pipe

During handling of the above exception, another exception occurred:

Traceback (most recent call last):
  File "/home/hugo/anaconda3/lib/python3.12/site-packages/wandb/sdk/lib/redirect.py", line 662, in _on_write
    cb(written_data)
  File "/home/hugo/anaconda3/lib/python3.12/site-packages/wandb/sdk/wandb_run.py", line 2487, in <lambda>
    lambda data: self._console_raw_callback("stdout", data),
                 ^^^^^^^^^^^^^^^^^^^^^^^^^^^^^^^^^^^^^^^^^^
  File "/home/hugo/anaconda3/lib/python3.12/site-packages/wandb/sdk/wandb_run.py", line 406, in wrapper
    return func(self, *args, **kwargs)
           ^^^^^^^^^^^^^^^^^^^^^^^^^^^
  File "/home/hugo/anaconda3/lib/python3.12/site-packages/wandb/sdk/wandb_run.py", line 464, in wrapper_fn
    return func(self, *args, **kwargs)
           ^^^^^^^^^^^^^^^^^^^^^^^^^^^
  File "/home/hugo/anaconda3/lib/python3.12/site-packages/wandb/sdk/wandb_run.py", line 1632, in _console_raw_callback
    self._backend.interface.publish_output_raw(name, data)
  File "/home/hugo/anaconda3/lib/python3.12/site-packages/wandb/sdk/interface/interface.py", line 763, in publish_output_raw
    self._publish_output_raw(o)
  File "/home/hugo/anaconda3/lib/python3.12/site-packages/wandb/sdk/interface/interface_shared.py", line 38, in _publish_output_raw
    self._publish(rec)
  File "/home/hugo/anaconda3/lib/python3.12/site-packages/wandb/sdk/interface/interface_sock.py", line 39, in _publish
    self._sock_client.send_record_publish(record)
  File "/home/hugo/anaconda3/lib/python3.12/site-packages/wandb/sdk/lib/sock_client.py", line 174, in send_record_publish
    self.send_server_request(server_req)
  File "/home/hugo/anaconda3/lib/python3.12/site-packages/wandb/sdk/lib/sock_client.py", line 154, in send_server_request
    self._send_message(msg)
  File "/home/hugo/anaconda3/lib/python3.12/site-packages/wandb/sdk/lib/sock_client.py", line 151, in _send_message
    self._sendall_with_error_handle(header + data)
  File "/home/hugo/anaconda3/lib/python3.12/site-packages/wandb/sdk/lib/sock_client.py", line 130, in _sendall_with_error_handle
    sent = self._sock.send(data)
           ^^^^^^^^^^^^^^^^^^^^^
BrokenPipeError: [Errno 32] Broken pipe
2025-05-26 20:48:07,417 ERROR   MainThread:16403 [redirect.py:_on_write():664] [no run ID] error in stdout callback
Traceback (most recent call last):
  File "/home/hugo/anaconda3/lib/python3.12/site-packages/IPython/core/events.py", line 82, in trigger
    func(*args, **kwargs)
  File "/home/hugo/anaconda3/lib/python3.12/site-packages/wandb/sdk/wandb_init.py", line 603, in _pre_run_cell_hook
    self.backend.interface.publish_pause()
  File "/home/hugo/anaconda3/lib/python3.12/site-packages/wandb/sdk/interface/interface.py", line 771, in publish_pause
    self._publish_pause(pause)
  File "/home/hugo/anaconda3/lib/python3.12/site-packages/wandb/sdk/interface/interface_shared.py", line 289, in _publish_pause
    self._publish(rec)
  File "/home/hugo/anaconda3/lib/python3.12/site-packages/wandb/sdk/interface/interface_sock.py", line 39, in _publish
    self._sock_client.send_record_publish(record)
  File "/home/hugo/anaconda3/lib/python3.12/site-packages/wandb/sdk/lib/sock_client.py", line 174, in send_record_publish
    self.send_server_request(server_req)
  File "/home/hugo/anaconda3/lib/python3.12/site-packages/wandb/sdk/lib/sock_client.py", line 154, in send_server_request
    self._send_message(msg)
  File "/home/hugo/anaconda3/lib/python3.12/site-packages/wandb/sdk/lib/sock_client.py", line 151, in _send_message
    self._sendall_with_error_handle(header + data)
  File "/home/hugo/anaconda3/lib/python3.12/site-packages/wandb/sdk/lib/sock_client.py", line 130, in _sendall_with_error_handle
    sent = self._sock.send(data)
           ^^^^^^^^^^^^^^^^^^^^^
BrokenPipeError: [Errno 32] Broken pipe

During handling of the above exception, another exception occurred:

Traceback (most recent call last):
  File "/home/hugo/anaconda3/lib/python3.12/site-packages/wandb/sdk/lib/redirect.py", line 662, in _on_write
    cb(written_data)
  File "/home/hugo/anaconda3/lib/python3.12/site-packages/wandb/sdk/wandb_run.py", line 2487, in <lambda>
    lambda data: self._console_raw_callback("stdout", data),
                 ^^^^^^^^^^^^^^^^^^^^^^^^^^^^^^^^^^^^^^^^^^
  File "/home/hugo/anaconda3/lib/python3.12/site-packages/wandb/sdk/wandb_run.py", line 406, in wrapper
    return func(self, *args, **kwargs)
           ^^^^^^^^^^^^^^^^^^^^^^^^^^^
  File "/home/hugo/anaconda3/lib/python3.12/site-packages/wandb/sdk/wandb_run.py", line 464, in wrapper_fn
    return func(self, *args, **kwargs)
           ^^^^^^^^^^^^^^^^^^^^^^^^^^^
  File "/home/hugo/anaconda3/lib/python3.12/site-packages/wandb/sdk/wandb_run.py", line 1632, in _console_raw_callback
    self._backend.interface.publish_output_raw(name, data)
  File "/home/hugo/anaconda3/lib/python3.12/site-packages/wandb/sdk/interface/interface.py", line 763, in publish_output_raw
    self._publish_output_raw(o)
  File "/home/hugo/anaconda3/lib/python3.12/site-packages/wandb/sdk/interface/interface_shared.py", line 38, in _publish_output_raw
    self._publish(rec)
  File "/home/hugo/anaconda3/lib/python3.12/site-packages/wandb/sdk/interface/interface_sock.py", line 39, in _publish
    self._sock_client.send_record_publish(record)
  File "/home/hugo/anaconda3/lib/python3.12/site-packages/wandb/sdk/lib/sock_client.py", line 174, in send_record_publish
    self.send_server_request(server_req)
  File "/home/hugo/anaconda3/lib/python3.12/site-packages/wandb/sdk/lib/sock_client.py", line 154, in send_server_request
    self._send_message(msg)
  File "/home/hugo/anaconda3/lib/python3.12/site-packages/wandb/sdk/lib/sock_client.py", line 151, in _send_message
    self._sendall_with_error_handle(header + data)
  File "/home/hugo/anaconda3/lib/python3.12/site-packages/wandb/sdk/lib/sock_client.py", line 130, in _sendall_with_error_handle
    sent = self._sock.send(data)
           ^^^^^^^^^^^^^^^^^^^^^
BrokenPipeError: [Errno 32] Broken pipe
2025-05-26 20:48:07,444 INFO    MainThread:16403 [wandb_init.py:_post_run_cell_hook():613] [no run ID] resuming backend
2025-05-26 20:48:07,444 ERROR   MainThread:16403 [redirect.py:_on_write():664] [no run ID] error in stdout callback
Traceback (most recent call last):
  File "/home/hugo/anaconda3/lib/python3.12/site-packages/IPython/core/events.py", line 82, in trigger
    func(*args, **kwargs)
  File "/home/hugo/anaconda3/lib/python3.12/site-packages/wandb/sdk/wandb_init.py", line 614, in _post_run_cell_hook
    self.backend.interface.publish_resume()
  File "/home/hugo/anaconda3/lib/python3.12/site-packages/wandb/sdk/interface/interface.py", line 779, in publish_resume
    self._publish_resume(resume)
  File "/home/hugo/anaconda3/lib/python3.12/site-packages/wandb/sdk/interface/interface_shared.py", line 293, in _publish_resume
    self._publish(rec)
  File "/home/hugo/anaconda3/lib/python3.12/site-packages/wandb/sdk/interface/interface_sock.py", line 39, in _publish
    self._sock_client.send_record_publish(record)
  File "/home/hugo/anaconda3/lib/python3.12/site-packages/wandb/sdk/lib/sock_client.py", line 174, in send_record_publish
    self.send_server_request(server_req)
  File "/home/hugo/anaconda3/lib/python3.12/site-packages/wandb/sdk/lib/sock_client.py", line 154, in send_server_request
    self._send_message(msg)
  File "/home/hugo/anaconda3/lib/python3.12/site-packages/wandb/sdk/lib/sock_client.py", line 151, in _send_message
    self._sendall_with_error_handle(header + data)
  File "/home/hugo/anaconda3/lib/python3.12/site-packages/wandb/sdk/lib/sock_client.py", line 130, in _sendall_with_error_handle
    sent = self._sock.send(data)
           ^^^^^^^^^^^^^^^^^^^^^
BrokenPipeError: [Errno 32] Broken pipe

During handling of the above exception, another exception occurred:

Traceback (most recent call last):
  File "/home/hugo/anaconda3/lib/python3.12/site-packages/wandb/sdk/lib/redirect.py", line 662, in _on_write
    cb(written_data)
  File "/home/hugo/anaconda3/lib/python3.12/site-packages/wandb/sdk/wandb_run.py", line 2487, in <lambda>
    lambda data: self._console_raw_callback("stdout", data),
                 ^^^^^^^^^^^^^^^^^^^^^^^^^^^^^^^^^^^^^^^^^^
  File "/home/hugo/anaconda3/lib/python3.12/site-packages/wandb/sdk/wandb_run.py", line 406, in wrapper
    return func(self, *args, **kwargs)
           ^^^^^^^^^^^^^^^^^^^^^^^^^^^
  File "/home/hugo/anaconda3/lib/python3.12/site-packages/wandb/sdk/wandb_run.py", line 464, in wrapper_fn
    return func(self, *args, **kwargs)
           ^^^^^^^^^^^^^^^^^^^^^^^^^^^
  File "/home/hugo/anaconda3/lib/python3.12/site-packages/wandb/sdk/wandb_run.py", line 1632, in _console_raw_callback
    self._backend.interface.publish_output_raw(name, data)
  File "/home/hugo/anaconda3/lib/python3.12/site-packages/wandb/sdk/interface/interface.py", line 763, in publish_output_raw
    self._publish_output_raw(o)
  File "/home/hugo/anaconda3/lib/python3.12/site-packages/wandb/sdk/interface/interface_shared.py", line 38, in _publish_output_raw
    self._publish(rec)
  File "/home/hugo/anaconda3/lib/python3.12/site-packages/wandb/sdk/interface/interface_sock.py", line 39, in _publish
    self._sock_client.send_record_publish(record)
  File "/home/hugo/anaconda3/lib/python3.12/site-packages/wandb/sdk/lib/sock_client.py", line 174, in send_record_publish
    self.send_server_request(server_req)
  File "/home/hugo/anaconda3/lib/python3.12/site-packages/wandb/sdk/lib/sock_client.py", line 154, in send_server_request
    self._send_message(msg)
  File "/home/hugo/anaconda3/lib/python3.12/site-packages/wandb/sdk/lib/sock_client.py", line 151, in _send_message
    self._sendall_with_error_handle(header + data)
  File "/home/hugo/anaconda3/lib/python3.12/site-packages/wandb/sdk/lib/sock_client.py", line 130, in _sendall_with_error_handle
    sent = self._sock.send(data)
           ^^^^^^^^^^^^^^^^^^^^^
BrokenPipeError: [Errno 32] Broken pipe
2025-05-26 20:48:07,445 ERROR   MainThread:16403 [redirect.py:_on_write():664] [no run ID] error in stdout callback
Traceback (most recent call last):
  File "/home/hugo/anaconda3/lib/python3.12/site-packages/IPython/core/events.py", line 82, in trigger
    func(*args, **kwargs)
  File "/home/hugo/anaconda3/lib/python3.12/site-packages/wandb/sdk/wandb_init.py", line 614, in _post_run_cell_hook
    self.backend.interface.publish_resume()
  File "/home/hugo/anaconda3/lib/python3.12/site-packages/wandb/sdk/interface/interface.py", line 779, in publish_resume
    self._publish_resume(resume)
  File "/home/hugo/anaconda3/lib/python3.12/site-packages/wandb/sdk/interface/interface_shared.py", line 293, in _publish_resume
    self._publish(rec)
  File "/home/hugo/anaconda3/lib/python3.12/site-packages/wandb/sdk/interface/interface_sock.py", line 39, in _publish
    self._sock_client.send_record_publish(record)
  File "/home/hugo/anaconda3/lib/python3.12/site-packages/wandb/sdk/lib/sock_client.py", line 174, in send_record_publish
    self.send_server_request(server_req)
  File "/home/hugo/anaconda3/lib/python3.12/site-packages/wandb/sdk/lib/sock_client.py", line 154, in send_server_request
    self._send_message(msg)
  File "/home/hugo/anaconda3/lib/python3.12/site-packages/wandb/sdk/lib/sock_client.py", line 151, in _send_message
    self._sendall_with_error_handle(header + data)
  File "/home/hugo/anaconda3/lib/python3.12/site-packages/wandb/sdk/lib/sock_client.py", line 130, in _sendall_with_error_handle
    sent = self._sock.send(data)
           ^^^^^^^^^^^^^^^^^^^^^
BrokenPipeError: [Errno 32] Broken pipe

During handling of the above exception, another exception occurred:

Traceback (most recent call last):
  File "/home/hugo/anaconda3/lib/python3.12/site-packages/wandb/sdk/lib/redirect.py", line 662, in _on_write
    cb(written_data)
  File "/home/hugo/anaconda3/lib/python3.12/site-packages/wandb/sdk/wandb_run.py", line 2487, in <lambda>
    lambda data: self._console_raw_callback("stdout", data),
                 ^^^^^^^^^^^^^^^^^^^^^^^^^^^^^^^^^^^^^^^^^^
  File "/home/hugo/anaconda3/lib/python3.12/site-packages/wandb/sdk/wandb_run.py", line 406, in wrapper
    return func(self, *args, **kwargs)
           ^^^^^^^^^^^^^^^^^^^^^^^^^^^
  File "/home/hugo/anaconda3/lib/python3.12/site-packages/wandb/sdk/wandb_run.py", line 464, in wrapper_fn
    return func(self, *args, **kwargs)
           ^^^^^^^^^^^^^^^^^^^^^^^^^^^
  File "/home/hugo/anaconda3/lib/python3.12/site-packages/wandb/sdk/wandb_run.py", line 1632, in _console_raw_callback
    self._backend.interface.publish_output_raw(name, data)
  File "/home/hugo/anaconda3/lib/python3.12/site-packages/wandb/sdk/interface/interface.py", line 763, in publish_output_raw
    self._publish_output_raw(o)
  File "/home/hugo/anaconda3/lib/python3.12/site-packages/wandb/sdk/interface/interface_shared.py", line 38, in _publish_output_raw
    self._publish(rec)
  File "/home/hugo/anaconda3/lib/python3.12/site-packages/wandb/sdk/interface/interface_sock.py", line 39, in _publish
    self._sock_client.send_record_publish(record)
  File "/home/hugo/anaconda3/lib/python3.12/site-packages/wandb/sdk/lib/sock_client.py", line 174, in send_record_publish
    self.send_server_request(server_req)
  File "/home/hugo/anaconda3/lib/python3.12/site-packages/wandb/sdk/lib/sock_client.py", line 154, in send_server_request
    self._send_message(msg)
  File "/home/hugo/anaconda3/lib/python3.12/site-packages/wandb/sdk/lib/sock_client.py", line 151, in _send_message
    self._sendall_with_error_handle(header + data)
  File "/home/hugo/anaconda3/lib/python3.12/site-packages/wandb/sdk/lib/sock_client.py", line 130, in _sendall_with_error_handle
    sent = self._sock.send(data)
           ^^^^^^^^^^^^^^^^^^^^^
BrokenPipeError: [Errno 32] Broken pipe
2025-05-26 20:48:07,485 INFO    MainThread:16403 [jupyter.py:save_ipynb():401] [no run ID] not saving jupyter notebook
2025-05-26 20:48:07,485 INFO    MainThread:16403 [wandb_init.py:_pre_run_cell_hook():602] [no run ID] pausing backend
2025-05-26 20:48:07,486 ERROR   MainThread:16403 [redirect.py:_on_write():664] [no run ID] error in stdout callback
Traceback (most recent call last):
  File "/home/hugo/anaconda3/lib/python3.12/site-packages/IPython/core/events.py", line 82, in trigger
    func(*args, **kwargs)
  File "/home/hugo/anaconda3/lib/python3.12/site-packages/wandb/sdk/wandb_init.py", line 603, in _pre_run_cell_hook
    self.backend.interface.publish_pause()
  File "/home/hugo/anaconda3/lib/python3.12/site-packages/wandb/sdk/interface/interface.py", line 771, in publish_pause
    self._publish_pause(pause)
  File "/home/hugo/anaconda3/lib/python3.12/site-packages/wandb/sdk/interface/interface_shared.py", line 289, in _publish_pause
    self._publish(rec)
  File "/home/hugo/anaconda3/lib/python3.12/site-packages/wandb/sdk/interface/interface_sock.py", line 39, in _publish
    self._sock_client.send_record_publish(record)
  File "/home/hugo/anaconda3/lib/python3.12/site-packages/wandb/sdk/lib/sock_client.py", line 174, in send_record_publish
    self.send_server_request(server_req)
  File "/home/hugo/anaconda3/lib/python3.12/site-packages/wandb/sdk/lib/sock_client.py", line 154, in send_server_request
    self._send_message(msg)
  File "/home/hugo/anaconda3/lib/python3.12/site-packages/wandb/sdk/lib/sock_client.py", line 151, in _send_message
    self._sendall_with_error_handle(header + data)
  File "/home/hugo/anaconda3/lib/python3.12/site-packages/wandb/sdk/lib/sock_client.py", line 130, in _sendall_with_error_handle
    sent = self._sock.send(data)
           ^^^^^^^^^^^^^^^^^^^^^
BrokenPipeError: [Errno 32] Broken pipe

During handling of the above exception, another exception occurred:

Traceback (most recent call last):
  File "/home/hugo/anaconda3/lib/python3.12/site-packages/wandb/sdk/lib/redirect.py", line 662, in _on_write
    cb(written_data)
  File "/home/hugo/anaconda3/lib/python3.12/site-packages/wandb/sdk/wandb_run.py", line 2487, in <lambda>
    lambda data: self._console_raw_callback("stdout", data),
                 ^^^^^^^^^^^^^^^^^^^^^^^^^^^^^^^^^^^^^^^^^^
  File "/home/hugo/anaconda3/lib/python3.12/site-packages/wandb/sdk/wandb_run.py", line 406, in wrapper
    return func(self, *args, **kwargs)
           ^^^^^^^^^^^^^^^^^^^^^^^^^^^
  File "/home/hugo/anaconda3/lib/python3.12/site-packages/wandb/sdk/wandb_run.py", line 464, in wrapper_fn
    return func(self, *args, **kwargs)
           ^^^^^^^^^^^^^^^^^^^^^^^^^^^
  File "/home/hugo/anaconda3/lib/python3.12/site-packages/wandb/sdk/wandb_run.py", line 1632, in _console_raw_callback
    self._backend.interface.publish_output_raw(name, data)
  File "/home/hugo/anaconda3/lib/python3.12/site-packages/wandb/sdk/interface/interface.py", line 763, in publish_output_raw
    self._publish_output_raw(o)
  File "/home/hugo/anaconda3/lib/python3.12/site-packages/wandb/sdk/interface/interface_shared.py", line 38, in _publish_output_raw
    self._publish(rec)
  File "/home/hugo/anaconda3/lib/python3.12/site-packages/wandb/sdk/interface/interface_sock.py", line 39, in _publish
    self._sock_client.send_record_publish(record)
  File "/home/hugo/anaconda3/lib/python3.12/site-packages/wandb/sdk/lib/sock_client.py", line 174, in send_record_publish
    self.send_server_request(server_req)
  File "/home/hugo/anaconda3/lib/python3.12/site-packages/wandb/sdk/lib/sock_client.py", line 154, in send_server_request
    self._send_message(msg)
  File "/home/hugo/anaconda3/lib/python3.12/site-packages/wandb/sdk/lib/sock_client.py", line 151, in _send_message
    self._sendall_with_error_handle(header + data)
  File "/home/hugo/anaconda3/lib/python3.12/site-packages/wandb/sdk/lib/sock_client.py", line 130, in _sendall_with_error_handle
    sent = self._sock.send(data)
           ^^^^^^^^^^^^^^^^^^^^^
BrokenPipeError: [Errno 32] Broken pipe
2025-05-26 20:48:07,487 ERROR   MainThread:16403 [redirect.py:_on_write():664] [no run ID] error in stdout callback
Traceback (most recent call last):
  File "/home/hugo/anaconda3/lib/python3.12/site-packages/IPython/core/events.py", line 82, in trigger
    func(*args, **kwargs)
  File "/home/hugo/anaconda3/lib/python3.12/site-packages/wandb/sdk/wandb_init.py", line 603, in _pre_run_cell_hook
    self.backend.interface.publish_pause()
  File "/home/hugo/anaconda3/lib/python3.12/site-packages/wandb/sdk/interface/interface.py", line 771, in publish_pause
    self._publish_pause(pause)
  File "/home/hugo/anaconda3/lib/python3.12/site-packages/wandb/sdk/interface/interface_shared.py", line 289, in _publish_pause
    self._publish(rec)
  File "/home/hugo/anaconda3/lib/python3.12/site-packages/wandb/sdk/interface/interface_sock.py", line 39, in _publish
    self._sock_client.send_record_publish(record)
  File "/home/hugo/anaconda3/lib/python3.12/site-packages/wandb/sdk/lib/sock_client.py", line 174, in send_record_publish
    self.send_server_request(server_req)
  File "/home/hugo/anaconda3/lib/python3.12/site-packages/wandb/sdk/lib/sock_client.py", line 154, in send_server_request
    self._send_message(msg)
  File "/home/hugo/anaconda3/lib/python3.12/site-packages/wandb/sdk/lib/sock_client.py", line 151, in _send_message
    self._sendall_with_error_handle(header + data)
  File "/home/hugo/anaconda3/lib/python3.12/site-packages/wandb/sdk/lib/sock_client.py", line 130, in _sendall_with_error_handle
    sent = self._sock.send(data)
           ^^^^^^^^^^^^^^^^^^^^^
BrokenPipeError: [Errno 32] Broken pipe

During handling of the above exception, another exception occurred:

Traceback (most recent call last):
  File "/home/hugo/anaconda3/lib/python3.12/site-packages/wandb/sdk/lib/redirect.py", line 662, in _on_write
    cb(written_data)
  File "/home/hugo/anaconda3/lib/python3.12/site-packages/wandb/sdk/wandb_run.py", line 2487, in <lambda>
    lambda data: self._console_raw_callback("stdout", data),
                 ^^^^^^^^^^^^^^^^^^^^^^^^^^^^^^^^^^^^^^^^^^
  File "/home/hugo/anaconda3/lib/python3.12/site-packages/wandb/sdk/wandb_run.py", line 406, in wrapper
    return func(self, *args, **kwargs)
           ^^^^^^^^^^^^^^^^^^^^^^^^^^^
  File "/home/hugo/anaconda3/lib/python3.12/site-packages/wandb/sdk/wandb_run.py", line 464, in wrapper_fn
    return func(self, *args, **kwargs)
           ^^^^^^^^^^^^^^^^^^^^^^^^^^^
  File "/home/hugo/anaconda3/lib/python3.12/site-packages/wandb/sdk/wandb_run.py", line 1632, in _console_raw_callback
    self._backend.interface.publish_output_raw(name, data)
  File "/home/hugo/anaconda3/lib/python3.12/site-packages/wandb/sdk/interface/interface.py", line 763, in publish_output_raw
    self._publish_output_raw(o)
  File "/home/hugo/anaconda3/lib/python3.12/site-packages/wandb/sdk/interface/interface_shared.py", line 38, in _publish_output_raw
    self._publish(rec)
  File "/home/hugo/anaconda3/lib/python3.12/site-packages/wandb/sdk/interface/interface_sock.py", line 39, in _publish
    self._sock_client.send_record_publish(record)
  File "/home/hugo/anaconda3/lib/python3.12/site-packages/wandb/sdk/lib/sock_client.py", line 174, in send_record_publish
    self.send_server_request(server_req)
  File "/home/hugo/anaconda3/lib/python3.12/site-packages/wandb/sdk/lib/sock_client.py", line 154, in send_server_request
    self._send_message(msg)
  File "/home/hugo/anaconda3/lib/python3.12/site-packages/wandb/sdk/lib/sock_client.py", line 151, in _send_message
    self._sendall_with_error_handle(header + data)
  File "/home/hugo/anaconda3/lib/python3.12/site-packages/wandb/sdk/lib/sock_client.py", line 130, in _sendall_with_error_handle
    sent = self._sock.send(data)
           ^^^^^^^^^^^^^^^^^^^^^
BrokenPipeError: [Errno 32] Broken pipe
2025-05-26 20:48:07,517 INFO    MainThread:16403 [wandb_init.py:_post_run_cell_hook():613] [no run ID] resuming backend
2025-05-26 20:48:07,517 ERROR   MainThread:16403 [redirect.py:_on_write():664] [no run ID] error in stdout callback
Traceback (most recent call last):
  File "/home/hugo/anaconda3/lib/python3.12/site-packages/IPython/core/events.py", line 82, in trigger
    func(*args, **kwargs)
  File "/home/hugo/anaconda3/lib/python3.12/site-packages/wandb/sdk/wandb_init.py", line 614, in _post_run_cell_hook
    self.backend.interface.publish_resume()
  File "/home/hugo/anaconda3/lib/python3.12/site-packages/wandb/sdk/interface/interface.py", line 779, in publish_resume
    self._publish_resume(resume)
  File "/home/hugo/anaconda3/lib/python3.12/site-packages/wandb/sdk/interface/interface_shared.py", line 293, in _publish_resume
    self._publish(rec)
  File "/home/hugo/anaconda3/lib/python3.12/site-packages/wandb/sdk/interface/interface_sock.py", line 39, in _publish
    self._sock_client.send_record_publish(record)
  File "/home/hugo/anaconda3/lib/python3.12/site-packages/wandb/sdk/lib/sock_client.py", line 174, in send_record_publish
    self.send_server_request(server_req)
  File "/home/hugo/anaconda3/lib/python3.12/site-packages/wandb/sdk/lib/sock_client.py", line 154, in send_server_request
    self._send_message(msg)
  File "/home/hugo/anaconda3/lib/python3.12/site-packages/wandb/sdk/lib/sock_client.py", line 151, in _send_message
    self._sendall_with_error_handle(header + data)
  File "/home/hugo/anaconda3/lib/python3.12/site-packages/wandb/sdk/lib/sock_client.py", line 130, in _sendall_with_error_handle
    sent = self._sock.send(data)
           ^^^^^^^^^^^^^^^^^^^^^
BrokenPipeError: [Errno 32] Broken pipe

During handling of the above exception, another exception occurred:

Traceback (most recent call last):
  File "/home/hugo/anaconda3/lib/python3.12/site-packages/wandb/sdk/lib/redirect.py", line 662, in _on_write
    cb(written_data)
  File "/home/hugo/anaconda3/lib/python3.12/site-packages/wandb/sdk/wandb_run.py", line 2487, in <lambda>
    lambda data: self._console_raw_callback("stdout", data),
                 ^^^^^^^^^^^^^^^^^^^^^^^^^^^^^^^^^^^^^^^^^^
  File "/home/hugo/anaconda3/lib/python3.12/site-packages/wandb/sdk/wandb_run.py", line 406, in wrapper
    return func(self, *args, **kwargs)
           ^^^^^^^^^^^^^^^^^^^^^^^^^^^
  File "/home/hugo/anaconda3/lib/python3.12/site-packages/wandb/sdk/wandb_run.py", line 464, in wrapper_fn
    return func(self, *args, **kwargs)
           ^^^^^^^^^^^^^^^^^^^^^^^^^^^
  File "/home/hugo/anaconda3/lib/python3.12/site-packages/wandb/sdk/wandb_run.py", line 1632, in _console_raw_callback
    self._backend.interface.publish_output_raw(name, data)
  File "/home/hugo/anaconda3/lib/python3.12/site-packages/wandb/sdk/interface/interface.py", line 763, in publish_output_raw
    self._publish_output_raw(o)
  File "/home/hugo/anaconda3/lib/python3.12/site-packages/wandb/sdk/interface/interface_shared.py", line 38, in _publish_output_raw
    self._publish(rec)
  File "/home/hugo/anaconda3/lib/python3.12/site-packages/wandb/sdk/interface/interface_sock.py", line 39, in _publish
    self._sock_client.send_record_publish(record)
  File "/home/hugo/anaconda3/lib/python3.12/site-packages/wandb/sdk/lib/sock_client.py", line 174, in send_record_publish
    self.send_server_request(server_req)
  File "/home/hugo/anaconda3/lib/python3.12/site-packages/wandb/sdk/lib/sock_client.py", line 154, in send_server_request
    self._send_message(msg)
  File "/home/hugo/anaconda3/lib/python3.12/site-packages/wandb/sdk/lib/sock_client.py", line 151, in _send_message
    self._sendall_with_error_handle(header + data)
  File "/home/hugo/anaconda3/lib/python3.12/site-packages/wandb/sdk/lib/sock_client.py", line 130, in _sendall_with_error_handle
    sent = self._sock.send(data)
           ^^^^^^^^^^^^^^^^^^^^^
BrokenPipeError: [Errno 32] Broken pipe
2025-05-26 20:48:07,519 ERROR   MainThread:16403 [redirect.py:_on_write():664] [no run ID] error in stdout callback
Traceback (most recent call last):
  File "/home/hugo/anaconda3/lib/python3.12/site-packages/IPython/core/events.py", line 82, in trigger
    func(*args, **kwargs)
  File "/home/hugo/anaconda3/lib/python3.12/site-packages/wandb/sdk/wandb_init.py", line 614, in _post_run_cell_hook
    self.backend.interface.publish_resume()
  File "/home/hugo/anaconda3/lib/python3.12/site-packages/wandb/sdk/interface/interface.py", line 779, in publish_resume
    self._publish_resume(resume)
  File "/home/hugo/anaconda3/lib/python3.12/site-packages/wandb/sdk/interface/interface_shared.py", line 293, in _publish_resume
    self._publish(rec)
  File "/home/hugo/anaconda3/lib/python3.12/site-packages/wandb/sdk/interface/interface_sock.py", line 39, in _publish
    self._sock_client.send_record_publish(record)
  File "/home/hugo/anaconda3/lib/python3.12/site-packages/wandb/sdk/lib/sock_client.py", line 174, in send_record_publish
    self.send_server_request(server_req)
  File "/home/hugo/anaconda3/lib/python3.12/site-packages/wandb/sdk/lib/sock_client.py", line 154, in send_server_request
    self._send_message(msg)
  File "/home/hugo/anaconda3/lib/python3.12/site-packages/wandb/sdk/lib/sock_client.py", line 151, in _send_message
    self._sendall_with_error_handle(header + data)
  File "/home/hugo/anaconda3/lib/python3.12/site-packages/wandb/sdk/lib/sock_client.py", line 130, in _sendall_with_error_handle
    sent = self._sock.send(data)
           ^^^^^^^^^^^^^^^^^^^^^
BrokenPipeError: [Errno 32] Broken pipe

During handling of the above exception, another exception occurred:

Traceback (most recent call last):
  File "/home/hugo/anaconda3/lib/python3.12/site-packages/wandb/sdk/lib/redirect.py", line 662, in _on_write
    cb(written_data)
  File "/home/hugo/anaconda3/lib/python3.12/site-packages/wandb/sdk/wandb_run.py", line 2487, in <lambda>
    lambda data: self._console_raw_callback("stdout", data),
                 ^^^^^^^^^^^^^^^^^^^^^^^^^^^^^^^^^^^^^^^^^^
  File "/home/hugo/anaconda3/lib/python3.12/site-packages/wandb/sdk/wandb_run.py", line 406, in wrapper
    return func(self, *args, **kwargs)
           ^^^^^^^^^^^^^^^^^^^^^^^^^^^
  File "/home/hugo/anaconda3/lib/python3.12/site-packages/wandb/sdk/wandb_run.py", line 464, in wrapper_fn
    return func(self, *args, **kwargs)
           ^^^^^^^^^^^^^^^^^^^^^^^^^^^
  File "/home/hugo/anaconda3/lib/python3.12/site-packages/wandb/sdk/wandb_run.py", line 1632, in _console_raw_callback
    self._backend.interface.publish_output_raw(name, data)
  File "/home/hugo/anaconda3/lib/python3.12/site-packages/wandb/sdk/interface/interface.py", line 763, in publish_output_raw
    self._publish_output_raw(o)
  File "/home/hugo/anaconda3/lib/python3.12/site-packages/wandb/sdk/interface/interface_shared.py", line 38, in _publish_output_raw
    self._publish(rec)
  File "/home/hugo/anaconda3/lib/python3.12/site-packages/wandb/sdk/interface/interface_sock.py", line 39, in _publish
    self._sock_client.send_record_publish(record)
  File "/home/hugo/anaconda3/lib/python3.12/site-packages/wandb/sdk/lib/sock_client.py", line 174, in send_record_publish
    self.send_server_request(server_req)
  File "/home/hugo/anaconda3/lib/python3.12/site-packages/wandb/sdk/lib/sock_client.py", line 154, in send_server_request
    self._send_message(msg)
  File "/home/hugo/anaconda3/lib/python3.12/site-packages/wandb/sdk/lib/sock_client.py", line 151, in _send_message
    self._sendall_with_error_handle(header + data)
  File "/home/hugo/anaconda3/lib/python3.12/site-packages/wandb/sdk/lib/sock_client.py", line 130, in _sendall_with_error_handle
    sent = self._sock.send(data)
           ^^^^^^^^^^^^^^^^^^^^^
BrokenPipeError: [Errno 32] Broken pipe
2025-05-26 20:48:07,554 INFO    MainThread:16403 [jupyter.py:save_ipynb():401] [no run ID] not saving jupyter notebook
2025-05-26 20:48:07,554 INFO    MainThread:16403 [wandb_init.py:_pre_run_cell_hook():602] [no run ID] pausing backend
2025-05-26 20:48:07,555 ERROR   MainThread:16403 [redirect.py:_on_write():664] [no run ID] error in stdout callback
Traceback (most recent call last):
  File "/home/hugo/anaconda3/lib/python3.12/site-packages/IPython/core/events.py", line 82, in trigger
    func(*args, **kwargs)
  File "/home/hugo/anaconda3/lib/python3.12/site-packages/wandb/sdk/wandb_init.py", line 603, in _pre_run_cell_hook
    self.backend.interface.publish_pause()
  File "/home/hugo/anaconda3/lib/python3.12/site-packages/wandb/sdk/interface/interface.py", line 771, in publish_pause
    self._publish_pause(pause)
  File "/home/hugo/anaconda3/lib/python3.12/site-packages/wandb/sdk/interface/interface_shared.py", line 289, in _publish_pause
    self._publish(rec)
  File "/home/hugo/anaconda3/lib/python3.12/site-packages/wandb/sdk/interface/interface_sock.py", line 39, in _publish
    self._sock_client.send_record_publish(record)
  File "/home/hugo/anaconda3/lib/python3.12/site-packages/wandb/sdk/lib/sock_client.py", line 174, in send_record_publish
    self.send_server_request(server_req)
  File "/home/hugo/anaconda3/lib/python3.12/site-packages/wandb/sdk/lib/sock_client.py", line 154, in send_server_request
    self._send_message(msg)
  File "/home/hugo/anaconda3/lib/python3.12/site-packages/wandb/sdk/lib/sock_client.py", line 151, in _send_message
    self._sendall_with_error_handle(header + data)
  File "/home/hugo/anaconda3/lib/python3.12/site-packages/wandb/sdk/lib/sock_client.py", line 130, in _sendall_with_error_handle
    sent = self._sock.send(data)
           ^^^^^^^^^^^^^^^^^^^^^
BrokenPipeError: [Errno 32] Broken pipe

During handling of the above exception, another exception occurred:

Traceback (most recent call last):
  File "/home/hugo/anaconda3/lib/python3.12/site-packages/wandb/sdk/lib/redirect.py", line 662, in _on_write
    cb(written_data)
  File "/home/hugo/anaconda3/lib/python3.12/site-packages/wandb/sdk/wandb_run.py", line 2487, in <lambda>
    lambda data: self._console_raw_callback("stdout", data),
                 ^^^^^^^^^^^^^^^^^^^^^^^^^^^^^^^^^^^^^^^^^^
  File "/home/hugo/anaconda3/lib/python3.12/site-packages/wandb/sdk/wandb_run.py", line 406, in wrapper
    return func(self, *args, **kwargs)
           ^^^^^^^^^^^^^^^^^^^^^^^^^^^
  File "/home/hugo/anaconda3/lib/python3.12/site-packages/wandb/sdk/wandb_run.py", line 464, in wrapper_fn
    return func(self, *args, **kwargs)
           ^^^^^^^^^^^^^^^^^^^^^^^^^^^
  File "/home/hugo/anaconda3/lib/python3.12/site-packages/wandb/sdk/wandb_run.py", line 1632, in _console_raw_callback
    self._backend.interface.publish_output_raw(name, data)
  File "/home/hugo/anaconda3/lib/python3.12/site-packages/wandb/sdk/interface/interface.py", line 763, in publish_output_raw
    self._publish_output_raw(o)
  File "/home/hugo/anaconda3/lib/python3.12/site-packages/wandb/sdk/interface/interface_shared.py", line 38, in _publish_output_raw
    self._publish(rec)
  File "/home/hugo/anaconda3/lib/python3.12/site-packages/wandb/sdk/interface/interface_sock.py", line 39, in _publish
    self._sock_client.send_record_publish(record)
  File "/home/hugo/anaconda3/lib/python3.12/site-packages/wandb/sdk/lib/sock_client.py", line 174, in send_record_publish
    self.send_server_request(server_req)
  File "/home/hugo/anaconda3/lib/python3.12/site-packages/wandb/sdk/lib/sock_client.py", line 154, in send_server_request
    self._send_message(msg)
  File "/home/hugo/anaconda3/lib/python3.12/site-packages/wandb/sdk/lib/sock_client.py", line 151, in _send_message
    self._sendall_with_error_handle(header + data)
  File "/home/hugo/anaconda3/lib/python3.12/site-packages/wandb/sdk/lib/sock_client.py", line 130, in _sendall_with_error_handle
    sent = self._sock.send(data)
           ^^^^^^^^^^^^^^^^^^^^^
BrokenPipeError: [Errno 32] Broken pipe
2025-05-26 20:48:07,556 ERROR   MainThread:16403 [redirect.py:_on_write():664] [no run ID] error in stdout callback
Traceback (most recent call last):
  File "/home/hugo/anaconda3/lib/python3.12/site-packages/IPython/core/events.py", line 82, in trigger
    func(*args, **kwargs)
  File "/home/hugo/anaconda3/lib/python3.12/site-packages/wandb/sdk/wandb_init.py", line 603, in _pre_run_cell_hook
    self.backend.interface.publish_pause()
  File "/home/hugo/anaconda3/lib/python3.12/site-packages/wandb/sdk/interface/interface.py", line 771, in publish_pause
    self._publish_pause(pause)
  File "/home/hugo/anaconda3/lib/python3.12/site-packages/wandb/sdk/interface/interface_shared.py", line 289, in _publish_pause
    self._publish(rec)
  File "/home/hugo/anaconda3/lib/python3.12/site-packages/wandb/sdk/interface/interface_sock.py", line 39, in _publish
    self._sock_client.send_record_publish(record)
  File "/home/hugo/anaconda3/lib/python3.12/site-packages/wandb/sdk/lib/sock_client.py", line 174, in send_record_publish
    self.send_server_request(server_req)
  File "/home/hugo/anaconda3/lib/python3.12/site-packages/wandb/sdk/lib/sock_client.py", line 154, in send_server_request
    self._send_message(msg)
  File "/home/hugo/anaconda3/lib/python3.12/site-packages/wandb/sdk/lib/sock_client.py", line 151, in _send_message
    self._sendall_with_error_handle(header + data)
  File "/home/hugo/anaconda3/lib/python3.12/site-packages/wandb/sdk/lib/sock_client.py", line 130, in _sendall_with_error_handle
    sent = self._sock.send(data)
           ^^^^^^^^^^^^^^^^^^^^^
BrokenPipeError: [Errno 32] Broken pipe

During handling of the above exception, another exception occurred:

Traceback (most recent call last):
  File "/home/hugo/anaconda3/lib/python3.12/site-packages/wandb/sdk/lib/redirect.py", line 662, in _on_write
    cb(written_data)
  File "/home/hugo/anaconda3/lib/python3.12/site-packages/wandb/sdk/wandb_run.py", line 2487, in <lambda>
    lambda data: self._console_raw_callback("stdout", data),
                 ^^^^^^^^^^^^^^^^^^^^^^^^^^^^^^^^^^^^^^^^^^
  File "/home/hugo/anaconda3/lib/python3.12/site-packages/wandb/sdk/wandb_run.py", line 406, in wrapper
    return func(self, *args, **kwargs)
           ^^^^^^^^^^^^^^^^^^^^^^^^^^^
  File "/home/hugo/anaconda3/lib/python3.12/site-packages/wandb/sdk/wandb_run.py", line 464, in wrapper_fn
    return func(self, *args, **kwargs)
           ^^^^^^^^^^^^^^^^^^^^^^^^^^^
  File "/home/hugo/anaconda3/lib/python3.12/site-packages/wandb/sdk/wandb_run.py", line 1632, in _console_raw_callback
    self._backend.interface.publish_output_raw(name, data)
  File "/home/hugo/anaconda3/lib/python3.12/site-packages/wandb/sdk/interface/interface.py", line 763, in publish_output_raw
    self._publish_output_raw(o)
  File "/home/hugo/anaconda3/lib/python3.12/site-packages/wandb/sdk/interface/interface_shared.py", line 38, in _publish_output_raw
    self._publish(rec)
  File "/home/hugo/anaconda3/lib/python3.12/site-packages/wandb/sdk/interface/interface_sock.py", line 39, in _publish
    self._sock_client.send_record_publish(record)
  File "/home/hugo/anaconda3/lib/python3.12/site-packages/wandb/sdk/lib/sock_client.py", line 174, in send_record_publish
    self.send_server_request(server_req)
  File "/home/hugo/anaconda3/lib/python3.12/site-packages/wandb/sdk/lib/sock_client.py", line 154, in send_server_request
    self._send_message(msg)
  File "/home/hugo/anaconda3/lib/python3.12/site-packages/wandb/sdk/lib/sock_client.py", line 151, in _send_message
    self._sendall_with_error_handle(header + data)
  File "/home/hugo/anaconda3/lib/python3.12/site-packages/wandb/sdk/lib/sock_client.py", line 130, in _sendall_with_error_handle
    sent = self._sock.send(data)
           ^^^^^^^^^^^^^^^^^^^^^
BrokenPipeError: [Errno 32] Broken pipe
2025-05-26 20:48:07,584 INFO    MainThread:16403 [wandb_init.py:_post_run_cell_hook():613] [no run ID] resuming backend
2025-05-26 20:48:07,585 ERROR   MainThread:16403 [redirect.py:_on_write():664] [no run ID] error in stdout callback
Traceback (most recent call last):
  File "/home/hugo/anaconda3/lib/python3.12/site-packages/IPython/core/events.py", line 82, in trigger
    func(*args, **kwargs)
  File "/home/hugo/anaconda3/lib/python3.12/site-packages/wandb/sdk/wandb_init.py", line 614, in _post_run_cell_hook
    self.backend.interface.publish_resume()
  File "/home/hugo/anaconda3/lib/python3.12/site-packages/wandb/sdk/interface/interface.py", line 779, in publish_resume
    self._publish_resume(resume)
  File "/home/hugo/anaconda3/lib/python3.12/site-packages/wandb/sdk/interface/interface_shared.py", line 293, in _publish_resume
    self._publish(rec)
  File "/home/hugo/anaconda3/lib/python3.12/site-packages/wandb/sdk/interface/interface_sock.py", line 39, in _publish
    self._sock_client.send_record_publish(record)
  File "/home/hugo/anaconda3/lib/python3.12/site-packages/wandb/sdk/lib/sock_client.py", line 174, in send_record_publish
    self.send_server_request(server_req)
  File "/home/hugo/anaconda3/lib/python3.12/site-packages/wandb/sdk/lib/sock_client.py", line 154, in send_server_request
    self._send_message(msg)
  File "/home/hugo/anaconda3/lib/python3.12/site-packages/wandb/sdk/lib/sock_client.py", line 151, in _send_message
    self._sendall_with_error_handle(header + data)
  File "/home/hugo/anaconda3/lib/python3.12/site-packages/wandb/sdk/lib/sock_client.py", line 130, in _sendall_with_error_handle
    sent = self._sock.send(data)
           ^^^^^^^^^^^^^^^^^^^^^
BrokenPipeError: [Errno 32] Broken pipe

During handling of the above exception, another exception occurred:

Traceback (most recent call last):
  File "/home/hugo/anaconda3/lib/python3.12/site-packages/wandb/sdk/lib/redirect.py", line 662, in _on_write
    cb(written_data)
  File "/home/hugo/anaconda3/lib/python3.12/site-packages/wandb/sdk/wandb_run.py", line 2487, in <lambda>
    lambda data: self._console_raw_callback("stdout", data),
                 ^^^^^^^^^^^^^^^^^^^^^^^^^^^^^^^^^^^^^^^^^^
  File "/home/hugo/anaconda3/lib/python3.12/site-packages/wandb/sdk/wandb_run.py", line 406, in wrapper
    return func(self, *args, **kwargs)
           ^^^^^^^^^^^^^^^^^^^^^^^^^^^
  File "/home/hugo/anaconda3/lib/python3.12/site-packages/wandb/sdk/wandb_run.py", line 464, in wrapper_fn
    return func(self, *args, **kwargs)
           ^^^^^^^^^^^^^^^^^^^^^^^^^^^
  File "/home/hugo/anaconda3/lib/python3.12/site-packages/wandb/sdk/wandb_run.py", line 1632, in _console_raw_callback
    self._backend.interface.publish_output_raw(name, data)
  File "/home/hugo/anaconda3/lib/python3.12/site-packages/wandb/sdk/interface/interface.py", line 763, in publish_output_raw
    self._publish_output_raw(o)
  File "/home/hugo/anaconda3/lib/python3.12/site-packages/wandb/sdk/interface/interface_shared.py", line 38, in _publish_output_raw
    self._publish(rec)
  File "/home/hugo/anaconda3/lib/python3.12/site-packages/wandb/sdk/interface/interface_sock.py", line 39, in _publish
    self._sock_client.send_record_publish(record)
  File "/home/hugo/anaconda3/lib/python3.12/site-packages/wandb/sdk/lib/sock_client.py", line 174, in send_record_publish
    self.send_server_request(server_req)
  File "/home/hugo/anaconda3/lib/python3.12/site-packages/wandb/sdk/lib/sock_client.py", line 154, in send_server_request
    self._send_message(msg)
  File "/home/hugo/anaconda3/lib/python3.12/site-packages/wandb/sdk/lib/sock_client.py", line 151, in _send_message
    self._sendall_with_error_handle(header + data)
  File "/home/hugo/anaconda3/lib/python3.12/site-packages/wandb/sdk/lib/sock_client.py", line 130, in _sendall_with_error_handle
    sent = self._sock.send(data)
           ^^^^^^^^^^^^^^^^^^^^^
BrokenPipeError: [Errno 32] Broken pipe
2025-05-26 20:48:07,586 ERROR   MainThread:16403 [redirect.py:_on_write():664] [no run ID] error in stdout callback
Traceback (most recent call last):
  File "/home/hugo/anaconda3/lib/python3.12/site-packages/IPython/core/events.py", line 82, in trigger
    func(*args, **kwargs)
  File "/home/hugo/anaconda3/lib/python3.12/site-packages/wandb/sdk/wandb_init.py", line 614, in _post_run_cell_hook
    self.backend.interface.publish_resume()
  File "/home/hugo/anaconda3/lib/python3.12/site-packages/wandb/sdk/interface/interface.py", line 779, in publish_resume
    self._publish_resume(resume)
  File "/home/hugo/anaconda3/lib/python3.12/site-packages/wandb/sdk/interface/interface_shared.py", line 293, in _publish_resume
    self._publish(rec)
  File "/home/hugo/anaconda3/lib/python3.12/site-packages/wandb/sdk/interface/interface_sock.py", line 39, in _publish
    self._sock_client.send_record_publish(record)
  File "/home/hugo/anaconda3/lib/python3.12/site-packages/wandb/sdk/lib/sock_client.py", line 174, in send_record_publish
    self.send_server_request(server_req)
  File "/home/hugo/anaconda3/lib/python3.12/site-packages/wandb/sdk/lib/sock_client.py", line 154, in send_server_request
    self._send_message(msg)
  File "/home/hugo/anaconda3/lib/python3.12/site-packages/wandb/sdk/lib/sock_client.py", line 151, in _send_message
    self._sendall_with_error_handle(header + data)
  File "/home/hugo/anaconda3/lib/python3.12/site-packages/wandb/sdk/lib/sock_client.py", line 130, in _sendall_with_error_handle
    sent = self._sock.send(data)
           ^^^^^^^^^^^^^^^^^^^^^
BrokenPipeError: [Errno 32] Broken pipe

During handling of the above exception, another exception occurred:

Traceback (most recent call last):
  File "/home/hugo/anaconda3/lib/python3.12/site-packages/wandb/sdk/lib/redirect.py", line 662, in _on_write
    cb(written_data)
  File "/home/hugo/anaconda3/lib/python3.12/site-packages/wandb/sdk/wandb_run.py", line 2487, in <lambda>
    lambda data: self._console_raw_callback("stdout", data),
                 ^^^^^^^^^^^^^^^^^^^^^^^^^^^^^^^^^^^^^^^^^^
  File "/home/hugo/anaconda3/lib/python3.12/site-packages/wandb/sdk/wandb_run.py", line 406, in wrapper
    return func(self, *args, **kwargs)
           ^^^^^^^^^^^^^^^^^^^^^^^^^^^
  File "/home/hugo/anaconda3/lib/python3.12/site-packages/wandb/sdk/wandb_run.py", line 464, in wrapper_fn
    return func(self, *args, **kwargs)
           ^^^^^^^^^^^^^^^^^^^^^^^^^^^
  File "/home/hugo/anaconda3/lib/python3.12/site-packages/wandb/sdk/wandb_run.py", line 1632, in _console_raw_callback
    self._backend.interface.publish_output_raw(name, data)
  File "/home/hugo/anaconda3/lib/python3.12/site-packages/wandb/sdk/interface/interface.py", line 763, in publish_output_raw
    self._publish_output_raw(o)
  File "/home/hugo/anaconda3/lib/python3.12/site-packages/wandb/sdk/interface/interface_shared.py", line 38, in _publish_output_raw
    self._publish(rec)
  File "/home/hugo/anaconda3/lib/python3.12/site-packages/wandb/sdk/interface/interface_sock.py", line 39, in _publish
    self._sock_client.send_record_publish(record)
  File "/home/hugo/anaconda3/lib/python3.12/site-packages/wandb/sdk/lib/sock_client.py", line 174, in send_record_publish
    self.send_server_request(server_req)
  File "/home/hugo/anaconda3/lib/python3.12/site-packages/wandb/sdk/lib/sock_client.py", line 154, in send_server_request
    self._send_message(msg)
  File "/home/hugo/anaconda3/lib/python3.12/site-packages/wandb/sdk/lib/sock_client.py", line 151, in _send_message
    self._sendall_with_error_handle(header + data)
  File "/home/hugo/anaconda3/lib/python3.12/site-packages/wandb/sdk/lib/sock_client.py", line 130, in _sendall_with_error_handle
    sent = self._sock.send(data)
           ^^^^^^^^^^^^^^^^^^^^^
BrokenPipeError: [Errno 32] Broken pipe
2025-05-26 20:48:07,652 INFO    MainThread:16403 [jupyter.py:save_ipynb():401] [no run ID] not saving jupyter notebook
2025-05-26 20:48:07,653 INFO    MainThread:16403 [wandb_init.py:_pre_run_cell_hook():602] [no run ID] pausing backend
2025-05-26 20:48:07,653 ERROR   MainThread:16403 [redirect.py:_on_write():664] [no run ID] error in stdout callback
Traceback (most recent call last):
  File "/home/hugo/anaconda3/lib/python3.12/site-packages/IPython/core/events.py", line 82, in trigger
    func(*args, **kwargs)
  File "/home/hugo/anaconda3/lib/python3.12/site-packages/wandb/sdk/wandb_init.py", line 603, in _pre_run_cell_hook
    self.backend.interface.publish_pause()
  File "/home/hugo/anaconda3/lib/python3.12/site-packages/wandb/sdk/interface/interface.py", line 771, in publish_pause
    self._publish_pause(pause)
  File "/home/hugo/anaconda3/lib/python3.12/site-packages/wandb/sdk/interface/interface_shared.py", line 289, in _publish_pause
    self._publish(rec)
  File "/home/hugo/anaconda3/lib/python3.12/site-packages/wandb/sdk/interface/interface_sock.py", line 39, in _publish
    self._sock_client.send_record_publish(record)
  File "/home/hugo/anaconda3/lib/python3.12/site-packages/wandb/sdk/lib/sock_client.py", line 174, in send_record_publish
    self.send_server_request(server_req)
  File "/home/hugo/anaconda3/lib/python3.12/site-packages/wandb/sdk/lib/sock_client.py", line 154, in send_server_request
    self._send_message(msg)
  File "/home/hugo/anaconda3/lib/python3.12/site-packages/wandb/sdk/lib/sock_client.py", line 151, in _send_message
    self._sendall_with_error_handle(header + data)
  File "/home/hugo/anaconda3/lib/python3.12/site-packages/wandb/sdk/lib/sock_client.py", line 130, in _sendall_with_error_handle
    sent = self._sock.send(data)
           ^^^^^^^^^^^^^^^^^^^^^
BrokenPipeError: [Errno 32] Broken pipe

During handling of the above exception, another exception occurred:

Traceback (most recent call last):
  File "/home/hugo/anaconda3/lib/python3.12/site-packages/wandb/sdk/lib/redirect.py", line 662, in _on_write
    cb(written_data)
  File "/home/hugo/anaconda3/lib/python3.12/site-packages/wandb/sdk/wandb_run.py", line 2487, in <lambda>
    lambda data: self._console_raw_callback("stdout", data),
                 ^^^^^^^^^^^^^^^^^^^^^^^^^^^^^^^^^^^^^^^^^^
  File "/home/hugo/anaconda3/lib/python3.12/site-packages/wandb/sdk/wandb_run.py", line 406, in wrapper
    return func(self, *args, **kwargs)
           ^^^^^^^^^^^^^^^^^^^^^^^^^^^
  File "/home/hugo/anaconda3/lib/python3.12/site-packages/wandb/sdk/wandb_run.py", line 464, in wrapper_fn
    return func(self, *args, **kwargs)
           ^^^^^^^^^^^^^^^^^^^^^^^^^^^
  File "/home/hugo/anaconda3/lib/python3.12/site-packages/wandb/sdk/wandb_run.py", line 1632, in _console_raw_callback
    self._backend.interface.publish_output_raw(name, data)
  File "/home/hugo/anaconda3/lib/python3.12/site-packages/wandb/sdk/interface/interface.py", line 763, in publish_output_raw
    self._publish_output_raw(o)
  File "/home/hugo/anaconda3/lib/python3.12/site-packages/wandb/sdk/interface/interface_shared.py", line 38, in _publish_output_raw
    self._publish(rec)
  File "/home/hugo/anaconda3/lib/python3.12/site-packages/wandb/sdk/interface/interface_sock.py", line 39, in _publish
    self._sock_client.send_record_publish(record)
  File "/home/hugo/anaconda3/lib/python3.12/site-packages/wandb/sdk/lib/sock_client.py", line 174, in send_record_publish
    self.send_server_request(server_req)
  File "/home/hugo/anaconda3/lib/python3.12/site-packages/wandb/sdk/lib/sock_client.py", line 154, in send_server_request
    self._send_message(msg)
  File "/home/hugo/anaconda3/lib/python3.12/site-packages/wandb/sdk/lib/sock_client.py", line 151, in _send_message
    self._sendall_with_error_handle(header + data)
  File "/home/hugo/anaconda3/lib/python3.12/site-packages/wandb/sdk/lib/sock_client.py", line 130, in _sendall_with_error_handle
    sent = self._sock.send(data)
           ^^^^^^^^^^^^^^^^^^^^^
BrokenPipeError: [Errno 32] Broken pipe
2025-05-26 20:48:07,654 ERROR   MainThread:16403 [redirect.py:_on_write():664] [no run ID] error in stdout callback
Traceback (most recent call last):
  File "/home/hugo/anaconda3/lib/python3.12/site-packages/IPython/core/events.py", line 82, in trigger
    func(*args, **kwargs)
  File "/home/hugo/anaconda3/lib/python3.12/site-packages/wandb/sdk/wandb_init.py", line 603, in _pre_run_cell_hook
    self.backend.interface.publish_pause()
  File "/home/hugo/anaconda3/lib/python3.12/site-packages/wandb/sdk/interface/interface.py", line 771, in publish_pause
    self._publish_pause(pause)
  File "/home/hugo/anaconda3/lib/python3.12/site-packages/wandb/sdk/interface/interface_shared.py", line 289, in _publish_pause
    self._publish(rec)
  File "/home/hugo/anaconda3/lib/python3.12/site-packages/wandb/sdk/interface/interface_sock.py", line 39, in _publish
    self._sock_client.send_record_publish(record)
  File "/home/hugo/anaconda3/lib/python3.12/site-packages/wandb/sdk/lib/sock_client.py", line 174, in send_record_publish
    self.send_server_request(server_req)
  File "/home/hugo/anaconda3/lib/python3.12/site-packages/wandb/sdk/lib/sock_client.py", line 154, in send_server_request
    self._send_message(msg)
  File "/home/hugo/anaconda3/lib/python3.12/site-packages/wandb/sdk/lib/sock_client.py", line 151, in _send_message
    self._sendall_with_error_handle(header + data)
  File "/home/hugo/anaconda3/lib/python3.12/site-packages/wandb/sdk/lib/sock_client.py", line 130, in _sendall_with_error_handle
    sent = self._sock.send(data)
           ^^^^^^^^^^^^^^^^^^^^^
BrokenPipeError: [Errno 32] Broken pipe

During handling of the above exception, another exception occurred:

Traceback (most recent call last):
  File "/home/hugo/anaconda3/lib/python3.12/site-packages/wandb/sdk/lib/redirect.py", line 662, in _on_write
    cb(written_data)
  File "/home/hugo/anaconda3/lib/python3.12/site-packages/wandb/sdk/wandb_run.py", line 2487, in <lambda>
    lambda data: self._console_raw_callback("stdout", data),
                 ^^^^^^^^^^^^^^^^^^^^^^^^^^^^^^^^^^^^^^^^^^
  File "/home/hugo/anaconda3/lib/python3.12/site-packages/wandb/sdk/wandb_run.py", line 406, in wrapper
    return func(self, *args, **kwargs)
           ^^^^^^^^^^^^^^^^^^^^^^^^^^^
  File "/home/hugo/anaconda3/lib/python3.12/site-packages/wandb/sdk/wandb_run.py", line 464, in wrapper_fn
    return func(self, *args, **kwargs)
           ^^^^^^^^^^^^^^^^^^^^^^^^^^^
  File "/home/hugo/anaconda3/lib/python3.12/site-packages/wandb/sdk/wandb_run.py", line 1632, in _console_raw_callback
    self._backend.interface.publish_output_raw(name, data)
  File "/home/hugo/anaconda3/lib/python3.12/site-packages/wandb/sdk/interface/interface.py", line 763, in publish_output_raw
    self._publish_output_raw(o)
  File "/home/hugo/anaconda3/lib/python3.12/site-packages/wandb/sdk/interface/interface_shared.py", line 38, in _publish_output_raw
    self._publish(rec)
  File "/home/hugo/anaconda3/lib/python3.12/site-packages/wandb/sdk/interface/interface_sock.py", line 39, in _publish
    self._sock_client.send_record_publish(record)
  File "/home/hugo/anaconda3/lib/python3.12/site-packages/wandb/sdk/lib/sock_client.py", line 174, in send_record_publish
    self.send_server_request(server_req)
  File "/home/hugo/anaconda3/lib/python3.12/site-packages/wandb/sdk/lib/sock_client.py", line 154, in send_server_request
    self._send_message(msg)
  File "/home/hugo/anaconda3/lib/python3.12/site-packages/wandb/sdk/lib/sock_client.py", line 151, in _send_message
    self._sendall_with_error_handle(header + data)
  File "/home/hugo/anaconda3/lib/python3.12/site-packages/wandb/sdk/lib/sock_client.py", line 130, in _sendall_with_error_handle
    sent = self._sock.send(data)
           ^^^^^^^^^^^^^^^^^^^^^
BrokenPipeError: [Errno 32] Broken pipe
