2025-05-27 18:46:35,455 INFO    MainThread:10263 [wandb_init.py:setup_run_log_directory():724] Logging user logs to /home/hugo/TFG/Notebooks/wandb/run-20250527_184635-78p263pb/logs/debug.log
2025-05-27 18:46:35,455 INFO    MainThread:10263 [wandb_init.py:setup_run_log_directory():725] Logging internal logs to /home/hugo/TFG/Notebooks/wandb/run-20250527_184635-78p263pb/logs/debug-internal.log
2025-05-27 18:46:35,455 INFO    MainThread:10263 [wandb_init.py:monkeypatch_ipython():643] configuring jupyter hooks <wandb.sdk.wandb_init._WandbInit object at 0x7a82e658c2c0>
2025-05-27 18:46:35,455 INFO    MainThread:10263 [wandb_init.py:init():852] calling init triggers
2025-05-27 18:46:35,455 INFO    MainThread:10263 [wandb_init.py:init():857] wandb.init called with sweep_config: {}
config: {'batch_size': 32, 'learning_rate': 0.01, 'hidden_size': 25, 'epochs': 50, 'fold': 1, '_wandb': {}}
2025-05-27 18:46:35,455 INFO    MainThread:10263 [wandb_init.py:init():893] starting backend
2025-05-27 18:46:35,456 INFO    MainThread:10263 [wandb_init.py:init():897] sending inform_init request
2025-05-27 18:46:35,457 INFO    MainThread:10263 [backend.py:_multiprocessing_setup():101] multiprocessing start_methods=fork,spawn,forkserver, using: spawn
2025-05-27 18:46:35,457 INFO    MainThread:10263 [wandb_init.py:init():907] backend started and connected
2025-05-27 18:46:35,462 INFO    MainThread:10263 [wandb_run.py:_label_probe_notebook():1369] probe notebook
2025-05-27 18:46:35,463 INFO    MainThread:10263 [wandb_init.py:init():1002] updated telemetry
2025-05-27 18:46:35,470 INFO    MainThread:10263 [wandb_init.py:init():1026] communicating run to backend with 90.0 second timeout
2025-05-27 18:46:36,075 INFO    MainThread:10263 [wandb_init.py:init():1101] starting run threads in backend
2025-05-27 18:46:36,354 INFO    MainThread:10263 [wandb_run.py:_console_start():2566] atexit reg
2025-05-27 18:46:36,355 INFO    MainThread:10263 [wandb_run.py:_redirect():2414] redirect: wrap_raw
2025-05-27 18:46:36,355 INFO    MainThread:10263 [wandb_run.py:_redirect():2483] Wrapping output streams.
2025-05-27 18:46:36,356 INFO    MainThread:10263 [wandb_run.py:_redirect():2506] Redirects installed.
2025-05-27 18:46:36,357 INFO    MainThread:10263 [wandb_init.py:init():1147] run started, returning control to user process
2025-05-27 18:46:39,152 WARNING MsgRouterThr:10263 [router.py:message_loop():63] [no run ID] message_loop has been closed
Traceback (most recent call last):
  File "/home/hugo/anaconda3/lib/python3.12/site-packages/wandb/sdk/interface/router_sock.py", line 27, in _read_message
    return self._sock_client.read_server_response(timeout=1)
           ^^^^^^^^^^^^^^^^^^^^^^^^^^^^^^^^^^^^^^^^^^^^^^^^^
  File "/home/hugo/anaconda3/lib/python3.12/site-packages/wandb/sdk/lib/sock_client.py", line 235, in read_server_response
    data = self._read_packet_bytes(timeout=timeout)
           ^^^^^^^^^^^^^^^^^^^^^^^^^^^^^^^^^^^^^^^^
  File "/home/hugo/anaconda3/lib/python3.12/site-packages/wandb/sdk/lib/sock_client.py", line 220, in _read_packet_bytes
    raise SockClientClosedError
wandb.sdk.lib.sock_client.SockClientClosedError

The above exception was the direct cause of the following exception:

Traceback (most recent call last):
  File "/home/hugo/anaconda3/lib/python3.12/site-packages/wandb/sdk/interface/router.py", line 56, in message_loop
    msg = self._read_message()
          ^^^^^^^^^^^^^^^^^^^^
  File "/home/hugo/anaconda3/lib/python3.12/site-packages/wandb/sdk/interface/router_sock.py", line 29, in _read_message
    raise MessageRouterClosedError from e
wandb.sdk.interface.router.MessageRouterClosedError
2025-05-27 18:46:39,153 INFO    MsgRouterThr:10263 [mailbox.py:close():129] [no run ID] Closing mailbox, abandoning 7 handles.
2025-05-27 18:46:39,677 INFO    MainThread:10263 [wandb_init.py:_post_run_cell_hook():613] [no run ID] resuming backend
